Workbook
Name Slicer_Department: #N/A

Sheet Data
A1: FiscalYear | B1: Dept | C1: Quarter | D1: Budget ($) | E1: Forecast ($) | F1: Actual ($) | G1: Variance ($) | H1: Notes | K1: FiscalYear | L1: Quarter | M1: Dept | N1: Budget ($) | O1: Forecast ($) | P1: Actual ($) | Q1: Variance ($) | R1: Variance %
A2: 2024 | B2: Finance | C2: 1 | D2: 41215.19 | E2: 39758.93 | F2: 37613.91 | G2: =D2-F2 -> 3601.28 | K2: 2024 | L2: 1 | M2: Finance | N2: =SUMIFS(D:D,(A:A),$A$2,(C:C),$C$2,(B:B),$B$2) -> 41215.19 | O2: =SUMIFS(E:E,(A:A),$A$2,(C:C),$C$2,(B:B),$B$2) -> 39758.93 | P2: =SUMIFS(F:F,(A:A),$A$2,(C:C),$C$2,(B:B),$B$2) -> 37613.91 | Q2: =SUMIFS(G:G,(A:A),$A$2,(C:C),$C$2,(B:B),$B$2) -> 3601.28 | R2: =N2/P2-1 -> 0.095743303
A3: 2024 | B3: Finance | C3: 2 | D3: 79918.89 | E3: 84614.59 | F3: 86720.13 | G3: =D3-F3 -> -6801.24 | K3: 2024 | L3: 1 | M3: HR | N3: =SUMIFS(D:D,(A:A),$A$2,(C:C),$C$2,(B:B),$B$6) -> 32925.71 | O3: =SUMIFS(E:E,(A:A),$A$2,(C:C),$C$2,(B:B),$B$6) -> 30364.35 | P3: =SUMIFS(F:F,(A:A),$A$2,(C:C),$C$2,(B:B),$B$6) -> 30596.03 | Q3: =SUMIFS(G:G,(A:A),$A$2,(C:C),$C$2,(B:B),$B$6) -> 2329.68 | R3: =N3/P3-1 -> 0.076143212
A4: 2024 | B4: Finance | C4: 3 | D4: 92014.18 | E4: 100763.08 | F4: 105980.31 | G4: =D4-F4 -> -13966.13 | K4: 2024 | L4: 1 | M4: IT | N4: =SUMIFS(D:D,(A:A),$A$2,(C:C),$C$2,(B:B),$B$10) -> 26040.63 | O4: =SUMIFS(E:E,(A:A),$A$2,(C:C),$C$2,(B:B),$B$10) -> 24585.53 | P4: =SUMIFS(F:F,(A:A),$A$2,(C:C),$C$2,(B:B),$B$10) -> 22752.02 | Q4: =SUMIFS(G:G,(A:A),$A$2,(C:C),$C$2,(B:B),$B$10) -> 3288.61 | R4: =N4/P4-1 -> 0.14454145
A5: 2024 | B5: Finance | C5: 4 | D5: 117680.6 | E5: 106162.49 | F5: 96071.26 | G5: =D5-F5 -> 21609.34 | K5: 2024 | L5: 1 | M5: Marketing | N5: =SUMIFS(D:D,(A:A),$A$2,(C:C),$C$2,(B:B),$B$18) -> 44332.15 | O5: =SUMIFS(E:E,(A:A),$A$2,(C:C),$C$2,(B:B),$B$18) -> 41613.82 | P5: =SUMIFS(F:F,(A:A),$A$2,(C:C),$C$2,(B:B),$B$18) -> 38572.49 | Q5: =SUMIFS(G:G,(A:A),$A$2,(C:C),$C$2,(B:B),$B$18) -> 5759.66 | R5: =N5/P5-1 -> 0.14932041
A6: 2024 | B6: HR | C6: 1 | D6: 32925.71 | E6: 30364.35 | F6: 30596.03 | G6: =D6-F6 -> 2329.68 | K6: 2024 | L6: 1 | M6: Operations | N6: =SUMIFS(D:D,(A:A),$A$2,(C:C),$C$2,(B:B),$B$22) -> 100318.84 | O6: =SUMIFS(E:E,(A:A),$A$2,(C:C),$C$2,(B:B),$B$22) -> 99411.77 | P6: =SUMIFS(F:F,(A:A),$A$2,(C:C),$C$2,(B:B),$B$22) -> 102349.27 | Q6: =SUMIFS(G:G,(A:A),$A$2,(C:C),$C$2,(B:B),$B$22) -> -2030.43 | R6: =N6/P6-1 -> -0.019838246
A7: 2024 | B7: HR | C7: 2 | D7: 75074.82 | E7: 68249.88 | F7: 68953.81 | G7: =D7-F7 -> 6121.01 | K7: 2024 | L7: 1 | M7: Sales | N7: =SUMIFS(D:D,(A:A),$A$2,(C:C),$C$2,(B:B),$B$14) -> 93664.65 | O7: =SUMIFS(E:E,(A:A),$A$2,(C:C),$C$2,(B:B),$B$14) -> 99038.18 | P7: =SUMIFS(F:F,(A:A),$A$2,(C:C),$C$2,(B:B),$B$14) -> 105900.34 | Q7: =SUMIFS(G:G,(A:A),$A$2,(C:C),$C$2,(B:B),$B$14) -> -12235.69 | R7: =N7/P7-1 -> -0.11553967
A8: 2024 | B8: HR | C8: 3 | D8: 42503.06 | E8: 44444.3 | F8: 42652.11 | G8: =D8-F8 -> -149.05 | K8: 2024 | L8: 2 | M8: Finance | N8: =SUMIFS(D:D,(A:A),$A$2,(C:C),$C$3,(B:B),$B$2) -> 79918.89 | O8: =SUMIFS(E:E,(A:A),$A$2,(C:C),$C$3,(B:B),$B$2) -> 84614.59 | P8: =SUMIFS(F:F,(A:A),$A$2,(C:C),$C$3,(B:B),$B$2) -> 86720.13 | Q8: =SUMIFS(G:G,(A:A),$A$2,(C:C),$C$3,(B:B),$B$2) -> -6801.24 | R8: =N8/P8-1 -> -0.078427465
A9: 2024 | B9: HR | C9: 4 | D9: 31047.85 | E9: 32495.4 | F9: 33408.69 | G9: =D9-F9 -> -2360.84 | K9: 2024 | L9: 2 | M9: HR | N9: =SUMIFS(D:D,(A:A),$A$2,(C:C),$C$3,(B:B),$B$6) -> 75074.82 | O9: =SUMIFS(E:E,(A:A),$A$2,(C:C),$C$3,(B:B),$B$6) -> 68249.88 | P9: =SUMIFS(F:F,(A:A),$A$2,(C:C),$C$3,(B:B),$B$6) -> 68953.81 | Q9: =SUMIFS(G:G,(A:A),$A$2,(C:C),$C$3,(B:B),$B$6) -> 6121.01 | R9: =N9/P9-1 -> 0.088769714
A10: 2024 | B10: IT | C10: 1 | D10: 26040.63 | E10: 24585.53 | F10: 22752.02 | G10: =D10-F10 -> 3288.61 | K10: 2024 | L10: 2 | M10: IT | N10: =SUMIFS(D:D,(A:A),$A$2,(C:C),$C$3,(B:B),$B$10) -> 125902.24 | O10: =SUMIFS(E:E,(A:A),$A$2,(C:C),$C$3,(B:B),$B$10) -> 121557.94 | P10: =SUMIFS(F:F,(A:A),$A$2,(C:C),$C$3,(B:B),$B$10) -> 119490.08 | Q10: =SUMIFS(G:G,(A:A),$A$2,(C:C),$C$3,(B:B),$B$10) -> 6412.16 | R10: =N10/P10-1 -> 0.053662697
A11: 2024 | B11: IT | C11: 2 | D11: 125902.24 | E11: 121557.94 | F11: 119490.08 | G11: =D11-F11 -> 6412.16 | K11: 2024 | L11: 2 | M11: Marketing | N11: =SUMIFS(D:D,(A:A),$A$2,(C:C),$C$3,(B:B),$B$18) -> 112743.3 | O11: =SUMIFS(E:E,(A:A),$A$2,(C:C),$C$3,(B:B),$B$18) -> 119526.72 | P11: =SUMIFS(F:F,(A:A),$A$2,(C:C),$C$3,(B:B),$B$18) -> 125960.5 | Q11: =SUMIFS(G:G,(A:A),$A$2,(C:C),$C$3,(B:B),$B$18) -> -13217.2 | R11: =N11/P11-1 -> -0.10493131
A12: 2024 | B12: IT | C12: 3 | D12: 100055.73 | E12: 92809.65 | F12: 94502.07 | G12: =D12-F12 -> 5553.66 | K12: 2024 | L12: 2 | M12: Operations | N12: =SUMIFS(D:D,(A:A),$A$2,(C:C),$C$3,(B:B),$B$22) -> 51361.43 | O12: =SUMIFS(E:E,(A:A),$A$2,(C:C),$C$3,(B:B),$B$22) -> 49600.67 | P12: =SUMIFS(F:F,(A:A),$A$2,(C:C),$C$3,(B:B),$B$22) -> 50515.69 | Q12: =SUMIFS(G:G,(A:A),$A$2,(C:C),$C$3,(B:B),$B$22) -> 845.74 | R12: =N12/P12-1 -> 0.016742125
A13: 2024 | B13: IT | C13: 4 | D13: 72786.96 | E13: 70901.78 | F13: 72262.04 | G13: =D13-F13 -> 524.92 | K13: 2024 | L13: 2 | M13: Sales | N13: =SUMIFS(D:D,(A:A),$A$2,(C:C),$C$3,(B:B),$B$14) -> 115140.75 | O13: =SUMIFS(E:E,(A:A),$A$2,(C:C),$C$3,(B:B),$B$14) -> 115151.74 | P13: =SUMIFS(F:F,(A:A),$A$2,(C:C),$C$3,(B:B),$B$14) -> 124609.39 | Q13: =SUMIFS(G:G,(A:A),$A$2,(C:C),$C$3,(B:B),$B$14) -> -9468.64 | R13: =N13/P13-1 -> -0.075986569
A14: 2024 | B14: Sales | C14: 1 | D14: 93664.65 | E14: 99038.18 | F14: 105900.34 | G14: =D14-F14 -> -12235.69 | K14: 2024 | L14: 3 | M14: Finance | N14: =SUMIFS(D:D,(A:A),$A$2,(C:C),$C$4,(B:B),$B$2) -> 92014.18 | O14: =SUMIFS(E:E,(A:A),$A$2,(C:C),$C$4,(B:B),$B$2) -> 100763.08 | P14: =SUMIFS(F:F,(A:A),$A$2,(C:C),$C$4,(B:B),$B$2) -> 105980.31 | Q14: =SUMIFS(G:G,(A:A),$A$2,(C:C),$C$4,(B:B),$B$2) -> -13966.13 | R14: =N14/P14-1 -> -0.13178042
A15: 2024 | B15: Sales | C15: 2 | D15: 115140.75 | E15: 115151.74 | F15: 124609.39 | G15: =D15-F15 -> -9468.64 | K15: 2024 | L15: 3 | M15: HR | N15: =SUMIFS(D:D,(A:A),$A$2,(C:C),$C$4,(B:B),$B$6) -> 42503.06 | O15: =SUMIFS(E:E,(A:A),$A$2,(C:C),$C$4,(B:B),$B$6) -> 44444.3 | P15: =SUMIFS(F:F,(A:A),$A$2,(C:C),$C$4,(B:B),$B$6) -> 42652.11 | Q15: =SUMIFS(G:G,(A:A),$A$2,(C:C),$C$4,(B:B),$B$6) -> -149.05 | R15: =N15/P15-1 -> -0.0034945516
A16: 2024 | B16: Sales | C16: 3 | D16: 73898.42 | E16: 73799.15 | F16: 78992.61 | G16: =D16-F16 -> -5094.19 | K16: 2024 | L16: 3 | M16: IT | N16: =SUMIFS(D:D,(A:A),$A$2,(C:C),$C$4,(B:B),$B$10) -> 100055.73 | O16: =SUMIFS(E:E,(A:A),$A$2,(C:C),$C$4,(B:B),$B$10) -> 92809.65 | P16: =SUMIFS(F:F,(A:A),$A$2,(C:C),$C$4,(B:B),$B$10) -> 94502.07 | Q16: =SUMIFS(G:G,(A:A),$A$2,(C:C),$C$4,(B:B),$B$10) -> 5553.66 | R16: =N16/P16-1 -> 0.058767602
A17: 2024 | B17: Sales | C17: 4 | D17: 46637.67 | E17: 49635.65 | F17: 46802.25 | G17: =D17-F17 -> -164.58 | K17: 2024 | L17: 3 | M17: Marketing | N17: =SUMIFS(D:D,(A:A),$A$2,(C:C),$C$4,(B:B),$B$18) -> 141475.81 | O17: =SUMIFS(E:E,(A:A),$A$2,(C:C),$C$4,(B:B),$B$18) -> 133345.42 | P17: =SUMIFS(F:F,(A:A),$A$2,(C:C),$C$4,(B:B),$B$18) -> 140285.03 | Q17: =SUMIFS(G:G,(A:A),$A$2,(C:C),$C$4,(B:B),$B$18) -> 1190.78 | R17: =N17/P17-1 -> 0.0084882899
A18: 2024 | B18: Marketing | C18: 1 | D18: 44332.15 | E18: 41613.82 | F18: 38572.49 | G18: =D18-F18 -> 5759.66 | K18: 2024 | L18: 3 | M18: Operations | N18: =SUMIFS(D:D,(A:A),$A$2,(C:C),$C$4,(B:B),$B$22) -> 29263.69 | O18: =SUMIFS(E:E,(A:A),$A$2,(C:C),$C$4,(B:B),$B$22) -> 28094.51 | P18: =SUMIFS(F:F,(A:A),$A$2,(C:C),$C$4,(B:B),$B$22) -> 28496.35 | Q18: =SUMIFS(G:G,(A:A),$A$2,(C:C),$C$4,(B:B),$B$22) -> 767.34 | R18: =N18/P18-1 -> 0.026927659
A19: 2024 | B19: Marketing | C19: 2 | D19: 112743.3 | E19: 119526.72 | F19: 125960.5 | G19: =D19-F19 -> -13217.2 | K19: 2024 | L19: 3 | M19: Sales | N19: =SUMIFS(D:D,(A:A),$A$2,(C:C),$C$4,(B:B),$B$14) -> 73898.42 | O19: =SUMIFS(E:E,(A:A),$A$2,(C:C),$C$4,(B:B),$B$14) -> 73799.15 | P19: =SUMIFS(F:F,(A:A),$A$2,(C:C),$C$4,(B:B),$B$14) -> 78992.61 | Q19: =SUMIFS(G:G,(A:A),$A$2,(C:C),$C$4,(B:B),$B$14) -> -5094.19 | R19: =N19/P19-1 -> -0.06448945
A20: 2024 | B20: Marketing | C20: 3 | D20: 141475.81 | E20: 133345.42 | F20: 140285.03 | G20: =D20-F20 -> 1190.78 | K20: 2024 | L20: 4 | M20: Finance | N20: =SUMIFS(D:D,(A:A),$A$2,(C:C),$C$5,(B:B),$B$2) -> 117680.6 | O20: =SUMIFS(E:E,(A:A),$A$2,(C:C),$C$5,(B:B),$B$2) -> 106162.49 | P20: =SUMIFS(F:F,(A:A),$A$2,(C:C),$C$5,(B:B),$B$2) -> 96071.26 | Q20: =SUMIFS(G:G,(A:A),$A$2,(C:C),$C$5,(B:B),$B$2) -> 21609.34 | R20: =N20/P20-1 -> 0.22493033
A21: 2024 | B21: Marketing | C21: 4 | D21: 102519.44 | E21: 107453.3 | F21: 115251.53 | G21: =D21-F21 -> -12732.09 | K21: 2024 | L21: 4 | M21: HR | N21: =SUMIFS(D:D,(A:A),$A$2,(C:C),$C$5,(B:B),$B$6) -> 31047.85 | O21: =SUMIFS(E:E,(A:A),$A$2,(C:C),$C$5,(B:B),$B$6) -> 32495.4 | P21: =SUMIFS(F:F,(A:A),$A$2,(C:C),$C$5,(B:B),$B$6) -> 33408.69 | Q21: =SUMIFS(G:G,(A:A),$A$2,(C:C),$C$5,(B:B),$B$6) -> -2360.84 | R21: =N21/P21-1 -> -0.070665447
A22: 2024 | B22: Operations | C22: 1 | D22: 100318.84 | E22: 99411.77 | F22: 102349.27 | G22: =D22-F22 -> -2030.43 | K22: 2024 | L22: 4 | M22: IT | N22: =SUMIFS(D:D,(A:A),$A$2,(C:C),$C$5,(B:B),$B$10) -> 72786.96 | O22: =SUMIFS(E:E,(A:A),$A$2,(C:C),$C$5,(B:B),$B$10) -> 70901.78 | P22: =SUMIFS(F:F,(A:A),$A$2,(C:C),$C$5,(B:B),$B$10) -> 72262.04 | Q22: =SUMIFS(G:G,(A:A),$A$2,(C:C),$C$5,(B:B),$B$10) -> 524.92 | R22: =N22/P22-1 -> 0.0072641182
A23: 2024 | B23: Operations | C23: 2 | D23: 51361.43 | E23: 49600.67 | F23: 50515.69 | G23: =D23-F23 -> 845.74 | K23: 2024 | L23: 4 | M23: Marketing | N23: =SUMIFS(D:D,(A:A),$A$2,(C:C),$C$5,(B:B),$B$18) -> 102519.44 | O23: =SUMIFS(E:E,(A:A),$A$2,(C:C),$C$5,(B:B),$B$18) -> 107453.3 | P23: =SUMIFS(F:F,(A:A),$A$2,(C:C),$C$5,(B:B),$B$18) -> 115251.53 | Q23: =SUMIFS(G:G,(A:A),$A$2,(C:C),$C$5,(B:B),$B$18) -> -12732.09 | R23: =N23/P23-1 -> -0.1104722
A24: 2024 | B24: Operations | C24: 3 | D24: 29263.69 | E24: 28094.51 | F24: 28496.35 | G24: =D24-F24 -> 767.34 | K24: 2024 | L24: 4 | M24: Operations | N24: =SUMIFS(D:D,(A:A),$A$2,(C:C),$C$5,(B:B),$B$22) -> 146937.61 | O24: =SUMIFS(E:E,(A:A),$A$2,(C:C),$C$5,(B:B),$B$22) -> 139057.76 | P24: =SUMIFS(F:F,(A:A),$A$2,(C:C),$C$5,(B:B),$B$22) -> 147123.7 | Q24: =SUMIFS(G:G,(A:A),$A$2,(C:C),$C$5,(B:B),$B$22) -> -186.09 | R24: =N24/P24-1 -> -0.001264854
A25: 2024 | B25: Operations | C25: 4 | D25: 146937.61 | E25: 139057.76 | F25: 147123.7 | G25: =D25-F25 -> -186.09 | K25: 2024 | L25: 4 | M25: Sales | N25: =SUMIFS(D:D,(A:A),$A$2,(C:C),$C$5,(B:B),$B$14) -> 46637.67 | O25: =SUMIFS(E:E,(A:A),$A$2,(C:C),$C$5,(B:B),$B$14) -> 49635.65 | P25: =SUMIFS(F:F,(A:A),$A$2,(C:C),$C$5,(B:B),$B$14) -> 46802.25 | Q25: =SUMIFS(G:G,(A:A),$A$2,(C:C),$C$5,(B:B),$B$14) -> -164.58 | R25: =N25/P25-1 -> -0.0035164976
A26: 2025 | B26: Finance | C26: 1 | D26: 70700.52 | E26: 71487.46 | F26: 70006.17 | G26: =D26-F26 -> 694.35 | K26: 2025 | L26: 1 | M26: Finance | N26: =SUMIFS(D:D,(A:A),$A$26,(C:C),$C$2,(B:B),$B$2) -> 70700.52 | O26: =SUMIFS(E:E,(A:A),$A$26,(C:C),$C$2,(B:B),$B$2) -> 71487.46 | P26: =SUMIFS(F:F,(A:A),$A$26,(C:C),$C$2,(B:B),$B$2) -> 70006.17 | Q26: =SUMIFS(G:G,(A:A),$A$26,(C:C),$C$2,(B:B),$B$2) -> 694.35 | R26: =N26/P26-1 -> 0.0099184115
A27: 2025 | B27: Finance | C27: 2 | D27: 61495.92 | E27: 56931.54 | F27: 61359.25 | G27: =D27-F27 -> 136.67 | K27: 2025 | L27: 1 | M27: HR | N27: =SUMIFS(D:D,(A:A),$A$30,(C:C),$C$2,(B:B),$B$6) -> 81015.75 | O27: =SUMIFS(E:E,(A:A),$A$30,(C:C),$C$2,(B:B),$B$6) -> 81988.1 | P27: =SUMIFS(F:F,(A:A),$A$30,(C:C),$C$2,(B:B),$B$6) -> 86451.22 | Q27: =SUMIFS(G:G,(A:A),$A$30,(C:C),$C$2,(B:B),$B$6) -> -5435.47 | R27: =N27/P27-1 -> -0.06287326
A28: 2025 | B28: Finance | C28: 3 | D28: 55254.78 | E28: 57681.72 | F28: 57575 | G28: =D28-F28 -> -2320.22 | K28: 2025 | L28: 1 | M28: IT | N28: =SUMIFS(D:D,(A:A),$A$34,(C:C),$C$2,(B:B),$B$10) -> 116604.87 | O28: =SUMIFS(E:E,(A:A),$A$34,(C:C),$C$2,(B:B),$B$10) -> 125973.73 | P28: =SUMIFS(F:F,(A:A),$A$34,(C:C),$C$2,(B:B),$B$10) -> 128463.24 | Q28: =SUMIFS(G:G,(A:A),$A$34,(C:C),$C$2,(B:B),$B$10) -> -11858.37 | R28: =N28/P28-1 -> -0.092309442
A29: 2025 | B29: Finance | C29: 4 | D29: 124523.7 | E29: 112740.47 | F29: 118711.72 | G29: =D29-F29 -> 5811.98 | K29: 2025 | L29: 1 | M29: Marketing | N29: =SUMIFS(D:D,(A:A),$A$42,(C:C),$C$2,(B:B),$B$18) -> 75571.7 | O29: =SUMIFS(E:E,(A:A),$A$42,(C:C),$C$2,(B:B),$B$18) -> 80720.77 | P29: =SUMIFS(F:F,(A:A),$A$42,(C:C),$C$2,(B:B),$B$18) -> 86587.65 | Q29: =SUMIFS(G:G,(A:A),$A$2,(C:C),$C$2,(B:B),$B$18) -> 5759.66 | R29: =N29/P29-1 -> -0.12722311
A30: 2025 | B30: HR | C30: 1 | D30: 81015.75 | E30: 81988.1 | F30: 86451.22 | G30: =D30-F30 -> -5435.47 | K30: 2025 | L30: 1 | M30: Operations | N30: =SUMIFS(D:D,(A:A),$A$47,(C:C),$C$2,(B:B),$B$22) -> 64640.45 | O30: =SUMIFS(E:E,(A:A),$A$47,(C:C),$C$2,(B:B),$B$22) -> 70051.16 | P30: =SUMIFS(F:F,(A:A),$A$47,(C:C),$C$2,(B:B),$B$22) -> 66350.81 | Q30: =SUMIFS(G:G,(A:A),$A$47,(C:C),$C$2,(B:B),$B$22) -> -1710.36 | R30: =N30/P30-1 -> -0.02577753
A31: 2025 | B31: HR | C31: 2 | D31: 55099.41 | E31: 51780.92 | F31: 56227.09 | G31: =D31-F31 -> -1127.68 | K31: 2025 | L31: 1 | M31: Sales | N31: =SUMIFS(D:D,(A:A),$A$38,(C:C),$C$2,(B:B),$B$14) -> 89482.9 | O31: =SUMIFS(E:E,(A:A),$A$38,(C:C),$C$2,(B:B),$B$14) -> 97911.07 | P31: =SUMIFS(F:F,(A:A),$A$38,(C:C),$C$2,(B:B),$B$14) -> 98559.24 | Q31: =SUMIFS(G:G,(A:A),$A$38,(C:C),$C$2,(B:B),$B$14) -> -9076.34 | R31: =N31/P31-1 -> -0.092090199
A32: 2025 | B32: HR | C32: 3 | D32: 120462.05 | E32: 127306.15 | F32: 128022.17 | G32: =D32-F32 -> -7560.12 | K32: 2025 | L32: 2 | M32: Finance | N32: =SUMIFS(D:D,(A:A),$A$26,(C:C),$C$3,(B:B),$B$2) -> 61495.92 | O32: =SUMIFS(E:E,(A:A),$A$26,(C:C),$C$3,(B:B),$B$2) -> 56931.54 | P32: =SUMIFS(F:F,(A:A),$A$26,(C:C),$C$3,(B:B),$B$2) -> 61359.25 | Q32: =SUMIFS(G:G,(A:A),$A$26,(C:C),$C$3,(B:B),$B$2) -> 136.67 | R32: =N32/P32-1 -> 0.002227374
A33: 2025 | B33: HR | C33: 4 | D33: 90267.18 | E33: 85027.32 | F33: 88147.9 | G33: =D33-F33 -> 2119.28 | K33: 2025 | L33: 2 | M33: HR | N33: =SUMIFS(D:D,(A:A),$A$30,(C:C),$C$3,(B:B),$B$6) -> 55099.41 | O33: =SUMIFS(E:E,(A:A),$A$30,(C:C),$C$3,(B:B),$B$6) -> 51780.92 | P33: =SUMIFS(F:F,(A:A),$A$30,(C:C),$C$3,(B:B),$B$6) -> 56227.09 | Q33: =SUMIFS(G:G,(A:A),$A$30,(C:C),$C$3,(B:B),$B$6) -> -1127.68 | R33: =N33/P33-1 -> -0.020055813
A34: 2025 | B34: IT | C34: 1 | D34: 116604.87 | E34: 125973.73 | F34: 128463.24 | G34: =D34-F34 -> -11858.37 | K34: 2025 | L34: 2 | M34: IT | N34: =SUMIFS(D:D,(A:A),$A$34,(C:C),$C$3,(B:B),$B$10) -> 48595.51 | O34: =SUMIFS(E:E,(A:A),$A$34,(C:C),$C$3,(B:B),$B$10) -> 43972.66 | P34: =SUMIFS(F:F,(A:A),$A$34,(C:C),$C$3,(B:B),$B$10) -> 42981.29 | Q34: =SUMIFS(G:G,(A:A),$A$34,(C:C),$C$3,(B:B),$B$10) -> 5614.22 | R34: =N34/P34-1 -> 0.13062009
A35: 2025 | B35: IT | C35: 2 | D35: 48595.51 | E35: 43972.66 | F35: 42981.29 | G35: =D35-F35 -> 5614.22 | K35: 2025 | L35: 2 | M35: Marketing | N35: =SUMIFS(D:D,(A:A),$A$42,(C:C),$C$3,(B:B),$B$18) -> 130984.44 | O35: =SUMIFS(E:E,(A:A),$A$42,(C:C),$C$3,(B:B),$B$18) -> 142175.37 | P35: =SUMIFS(F:F,(A:A),$A$42,(C:C),$C$3,(B:B),$B$18) -> 145492.07 | Q35: =SUMIFS(G:G,(A:A),$A$2,(C:C),$C$3,(B:B),$B$18) -> -13217.2 | R35: =N35/P35-1 -> -0.099714232
A36: 2025 | B36: IT | C36: 3 | D36: 28599.2 | E36: 28718.48 | F36: 30923.94 | G36: =D36-F36 -> -2324.74 | K36: 2025 | L36: 2 | M36: Operations | N36: =SUMIFS(D:D,(A:A),$A$47,(C:C),$C$3,(B:B),$B$22) -> 21211.21 | O36: =SUMIFS(E:E,(A:A),$A$47,(C:C),$C$3,(B:B),$B$22) -> 22362.69 | P36: =SUMIFS(F:F,(A:A),$A$47,(C:C),$C$3,(B:B),$B$22) -> 22368.41 | Q36: =SUMIFS(G:G,(A:A),$A$47,(C:C),$C$3,(B:B),$B$22) -> -1157.2 | R36: =N36/P36-1 -> -0.051733673
A37: 2025 | B37: IT | C37: 4 | D37: 42077.12 | E37: 39403.9 | F37: 39330.25 | G37: =D37-F37 -> 2746.87 | K37: 2025 | L37: 2 | M37: Sales | N37: =SUMIFS(D:D,(A:A),$A$38,(C:C),$C$3,(B:B),$B$14) -> 66730.62 | O37: =SUMIFS(E:E,(A:A),$A$38,(C:C),$C$3,(B:B),$B$14) -> 63717.28 | P37: =SUMIFS(F:F,(A:A),$A$38,(C:C),$C$3,(B:B),$B$14) -> 67871.69 | Q37: =SUMIFS(G:G,(A:A),$A$38,(C:C),$C$3,(B:B),$B$14) -> -1141.07 | R37: =N37/P37-1 -> -0.016812164
A38: 2025 | B38: Sales | C38: 1 | D38: 89482.9 | E38: 97911.07 | F38: 98559.24 | G38: =D38-F38 -> -9076.34 | K38: 2025 | L38: 3 | M38: Finance | N38: =SUMIFS(D:D,(A:A),$A$26,(C:C),$C$4,(B:B),$B$2) -> 55254.78 | O38: =SUMIFS(E:E,(A:A),$A$26,(C:C),$C$4,(B:B),$B$2) -> 57681.72 | P38: =SUMIFS(F:F,(A:A),$A$26,(C:C),$C$4,(B:B),$B$2) -> 57575 | Q38: =SUMIFS(G:G,(A:A),$A$26,(C:C),$C$4,(B:B),$B$2) -> -2320.22 | R38: =N38/P38-1 -> -0.040299088
A39: 2025 | B39: Sales | C39: 2 | D39: 66730.62 | E39: 63717.28 | F39: 67871.69 | G39: =D39-F39 -> -1141.07 | K39: 2025 | L39: 3 | M39: HR | N39: =SUMIFS(D:D,(A:A),$A$30,(C:C),$C$4,(B:B),$B$6) -> 120462.05 | O39: =SUMIFS(E:E,(A:A),$A$30,(C:C),$C$4,(B:B),$B$6) -> 127306.15 | P39: =SUMIFS(F:F,(A:A),$A$30,(C:C),$C$4,(B:B),$B$6) -> 128022.17 | Q39: =SUMIFS(G:G,(A:A),$A$30,(C:C),$C$4,(B:B),$B$6) -> -7560.12 | R39: =N39/P39-1 -> -0.059053209
A40: 2025 | B40: Sales | C40: 3 | D40: 127969.04 | E40: 117894.18 | F40: 115938.14 | G40: =D40-F40 -> 12030.9 | K40: 2025 | L40: 3 | M40: IT | N40: =SUMIFS(D:D,(A:A),$A$34,(C:C),$C$4,(B:B),$B$10) -> 28599.2 | O40: =SUMIFS(E:E,(A:A),$A$34,(C:C),$C$4,(B:B),$B$10) -> 28718.48 | P40: =SUMIFS(F:F,(A:A),$A$34,(C:C),$C$4,(B:B),$B$10) -> 30923.94 | Q40: =SUMIFS(G:G,(A:A),$A$34,(C:C),$C$4,(B:B),$B$10) -> -2324.74 | R40: =N40/P40-1 -> -0.075176061
...

Sheet Dashboard
C2: Budget Vs Actual Analysis
C4: Current Year-> | D4: 2024
C5: Quarter | D5: 1
C7: Department | D7: Budget | E7: Forecast | F7: Actual | G7: Variance (Budget-Actual) | H7: Variance (Forecast-Actual) | I7: Variance (Budget-Actual)% | J7: Variance (Forecast-Actual) %
C8: Finance | D8: =SUMIFS(Data!$N:$N,Data!$K:$K,$D$4,Data!$L:$L,$D$5,Data!$M:$M,$C8) -> 41215.19 | E8: =SUMIFS(Data!$O:$O,Data!$K:$K,$D$4,Data!$L:$L,$D$5,Data!$M:$M,$C8) -> 39758.93 | F8: =SUMIFS(Data!$P:$P,Data!$K:$K,$D$4,Data!$L:$L,$D$5,Data!$M:$M,$C8) -> 37613.91 | G8: =D8-F8 -> 3601.28 | H8: =E8-F8 -> 2145.02 | I8: =D8/F8-1 -> 0.095743303 | J8: =E8/F8-1 -> 0.057027307
C9: HR | D9: =SUMIFS(Data!$N:$N,Data!$K:$K,$D$4,Data!$L:$L,$D$5,Data!$M:$M,$C9) -> 32925.71 | E9: =SUMIFS(Data!$O:$O,Data!$K:$K,$D$4,Data!$L:$L,$D$5,Data!$M:$M,$C9) -> 30364.35 | F9: =SUMIFS(Data!$P:$P,Data!$K:$K,$D$4,Data!$L:$L,$D$5,Data!$M:$M,$C9) -> 30596.03 | G9: =D9-F9 -> 2329.68 | H9: =E9-F9 -> -231.68 | I9: =D9/F9-1 -> 0.076143212 | J9: =E9/F9-1 -> -0.0075722242
C10: IT | D10: =SUMIFS(Data!$N:$N,Data!$K:$K,$D$4,Data!$L:$L,$D$5,Data!$M:$M,$C10) -> 26040.63 | E10: =SUMIFS(Data!$O:$O,Data!$K:$K,$D$4,Data!$L:$L,$D$5,Data!$M:$M,$C10) -> 24585.53 | F10: =SUMIFS(Data!$P:$P,Data!$K:$K,$D$4,Data!$L:$L,$D$5,Data!$M:$M,$C10) -> 22752.02 | G10: =D10-F10 -> 3288.61 | H10: =E10-F10 -> 1833.51 | I10: =D10/F10-1 -> 0.14454145 | J10: =E10/F10-1 -> 0.080586691
C11: Marketing | D11: =SUMIFS(Data!$N:$N,Data!$K:$K,$D$4,Data!$L:$L,$D$5,Data!$M:$M,$C11) -> 44332.15 | E11: =SUMIFS(Data!$O:$O,Data!$K:$K,$D$4,Data!$L:$L,$D$5,Data!$M:$M,$C11) -> 41613.82 | F11: =SUMIFS(Data!$P:$P,Data!$K:$K,$D$4,Data!$L:$L,$D$5,Data!$M:$M,$C11) -> 38572.49 | G11: =D11-F11 -> 5759.66 | H11: =E11-F11 -> 3041.33 | I11: =D11/F11-1 -> 0.14932041 | J11: =E11/F11-1 -> 0.078847127
C12: Operations | D12: =SUMIFS(Data!$N:$N,Data!$K:$K,$D$4,Data!$L:$L,$D$5,Data!$M:$M,$C12) -> 100318.84 | E12: =SUMIFS(Data!$O:$O,Data!$K:$K,$D$4,Data!$L:$L,$D$5,Data!$M:$M,$C12) -> 99411.77 | F12: =SUMIFS(Data!$P:$P,Data!$K:$K,$D$4,Data!$L:$L,$D$5,Data!$M:$M,$C12) -> 102349.27 | G12: =D12-F12 -> -2030.43 | H12: =E12-F12 -> -2937.5 | I12: =D12/F12-1 -> -0.019838246 | J12: =E12/F12-1 -> -0.028700742
C13: Sales | D13: =SUMIFS(Data!$N:$N,Data!$K:$K,$D$4,Data!$L:$L,$D$5,Data!$M:$M,$C13) -> 93664.65 | E13: =SUMIFS(Data!$O:$O,Data!$K:$K,$D$4,Data!$L:$L,$D$5,Data!$M:$M,$C13) -> 99038.18 | F13: =SUMIFS(Data!$P:$P,Data!$K:$K,$D$4,Data!$L:$L,$D$5,Data!$M:$M,$C13) -> 105900.34 | G13: =D13-F13 -> -12235.69 | H13: =E13-F13 -> -6862.16 | I13: =D13/F13-1 -> -0.11553967 | J13: =E13/F13-1 -> -0.064798281

Sheet Lists
B1: FiscalYear | H1: Quarter
B2: 2024 | H2: 1
B3: 2024 | E3: FiscalYear | H3: 2 | K3: Quarter
B4: 2024 | E4: 2024 | H4: 3 | K4: 1
B5: 2024 | E5: 2025 | H5: 4 | K5: 2
B6: 2024 | H6: 1 | K6: 3
B7: 2024 | H7: 2 | K7: 4
B8: 2024 | H8: 3
B9: 2024 | H9: 4
B10: 2024 | H10: 1
B11: 2024 | H11: 2
B12: 2024 | H12: 3
B13: 2024 | H13: 4
B14: 2024 | H14: 1
B15: 2024 | H15: 2
B16: 2024 | H16: 3
B17: 2024 | H17: 4
B18: 2024 | H18: 1
B19: 2024 | H19: 2
... B49: 2025 | H49: 4

Sheet Dashboard (2)
C2: Budget Vs Actual Analysis
C4: Current Year-> | D4: 2024
C5: Quarter | D5: 2
C7: Department | D7: Budget | E7: Forecast | F7: Actual | G7: Variance (Budget-Actual) | H7: Variance (Forecast-Actual) | I7: Variance (Budget-Actual)% | J7: Variance (Forecast-Actual) %
C8: Finance | D8: =SUMIFS(Data!$N:$N,Data!$K:$K,$D$4,Data!$L:$L,$D$5,Data!$M:$M,$C8) -> 79918.89 | E8: =SUMIFS(Data!$O:$O,Data!$K:$K,$D$4,Data!$L:$L,$D$5,Data!$M:$M,$C8) -> 84614.59 | F8: =SUMIFS(Data!$P:$P,Data!$K:$K,$D$4,Data!$L:$L,$D$5,Data!$M:$M,$C8) -> 86720.13 | G8: =D8-F8 -> -6801.24 | H8: =E8-F8 -> -2105.54 | I8: =D8/F8-1 -> -0.078427465 | J8: =E8/F8-1 -> -0.024279715
C9: HR | D9: =SUMIFS(Data!$N:$N,Data!$K:$K,$D$4,Data!$L:$L,$D$5,Data!$M:$M,$C9) -> 75074.82 | E9: =SUMIFS(Data!$O:$O,Data!$K:$K,$D$4,Data!$L:$L,$D$5,Data!$M:$M,$C9) -> 68249.88 | F9: =SUMIFS(Data!$P:$P,Data!$K:$K,$D$4,Data!$L:$L,$D$5,Data!$M:$M,$C9) -> 68953.81 | G9: =D9-F9 -> 6121.01 | H9: =E9-F9 -> -703.93 | I9: =D9/F9-1 -> 0.088769714 | J9: =E9/F9-1 -> -0.010208718
C10: IT | D10: =SUMIFS(Data!$N:$N,Data!$K:$K,$D$4,Data!$L:$L,$D$5,Data!$M:$M,$C10) -> 125902.24 | E10: =SUMIFS(Data!$O:$O,Data!$K:$K,$D$4,Data!$L:$L,$D$5,Data!$M:$M,$C10) -> 121557.94 | F10: =SUMIFS(Data!$P:$P,Data!$K:$K,$D$4,Data!$L:$L,$D$5,Data!$M:$M,$C10) -> 119490.08 | G10: =D10-F10 -> 6412.16 | H10: =E10-F10 -> 2067.86 | I10: =D10/F10-1 -> 0.053662697 | J10: =E10/F10-1 -> 0.017305704
C11: Marketing | D11: =SUMIFS(Data!$N:$N,Data!$K:$K,$D$4,Data!$L:$L,$D$5,Data!$M:$M,$C11) -> 112743.3 | E11: =SUMIFS(Data!$O:$O,Data!$K:$K,$D$4,Data!$L:$L,$D$5,Data!$M:$M,$C11) -> 119526.72 | F11: =SUMIFS(Data!$P:$P,Data!$K:$K,$D$4,Data!$L:$L,$D$5,Data!$M:$M,$C11) -> 125960.5 | G11: =D11-F11 -> -13217.2 | H11: =E11-F11 -> -6433.78 | I11: =D11/F11-1 -> -0.10493131 | J11: =E11/F11-1 -> -0.051077759
C12: Operations | D12: =SUMIFS(Data!$N:$N,Data!$K:$K,$D$4,Data!$L:$L,$D$5,Data!$M:$M,$C12) -> 51361.43 | E12: =SUMIFS(Data!$O:$O,Data!$K:$K,$D$4,Data!$L:$L,$D$5,Data!$M:$M,$C12) -> 49600.67 | F12: =SUMIFS(Data!$P:$P,Data!$K:$K,$D$4,Data!$L:$L,$D$5,Data!$M:$M,$C12) -> 50515.69 | G12: =D12-F12 -> 845.74 | H12: =E12-F12 -> -915.02 | I12: =D12/F12-1 -> 0.016742125 | J12: =E12/F12-1 -> -0.01811358
C13: Sales | D13: =SUMIFS(Data!$N:$N,Data!$K:$K,$D$4,Data!$L:$L,$D$5,Data!$M:$M,$C13) -> 115140.75 | E13: =SUMIFS(Data!$O:$O,Data!$K:$K,$D$4,Data!$L:$L,$D$5,Data!$M:$M,$C13) -> 115151.74 | F13: =SUMIFS(Data!$P:$P,Data!$K:$K,$D$4,Data!$L:$L,$D$5,Data!$M:$M,$C13) -> 124609.39 | G13: =D13-F13 -> -9468.64 | H13: =E13-F13 -> -9457.65 | I13: =D13/F13-1 -> -0.075986569 | J13: =E13/F13-1 -> -0.075898373
